Workbook
Name __123Graph_A: #REF!
Name __123Graph_B: #REF!
Name __123Graph_C: #REF!
Name __123Graph_D: #REF!
Name __123Graph_E: #REF!
Name __123Graph_F: #REF!
Name __123Graph_X: #REF!
Name __fa1: {"plansummary",#N/A,FALSE,"PlanSummary";"sales",#N/A,FALSE,"Sales Rec";"productivity",#N/A,FALSE,"Productivity Rec";"capitalspending",#N/A,FALSE,"Capital Spending"}
Name __fa2: {"plansummary",#N/A,FALSE,"PlanSummary";"sales",#N/A,FALSE,"Sales Rec";"productivity",#N/A,FALSE,"Productivity Rec";"capitalspending",#N/A,FALSE,"Capital Spending"}
Name __fa3: {"plansummary",#N/A,FALSE,"PlanSummary";"sales",#N/A,FALSE,"Sales Rec";"productivity",#N/A,FALSE,"Productivity Rec";"capitalspending",#N/A,FALSE,"Capital Spending"}
Name _Dist_Bin: #REF!
Name _Dist_Values: #REF!
Name _fa1: {"plansummary",#N/A,FALSE,"PlanSummary";"sales",#N/A,FALSE,"Sales Rec";"productivity",#N/A,FALSE,"Productivity Rec";"capitalspending",#N/A,FALSE,"Capital Spending"}
Name _fa2: {"plansummary",#N/A,FALSE,"PlanSummary";"sales",#N/A,FALSE,"Sales Rec";"productivity",#N/A,FALSE,"Productivity Rec";"capitalspending",#N/A,FALSE,"Capital Spending"}
Name _fa3: {"plansummary",#N/A,FALSE,"PlanSummary";"sales",#N/A,FALSE,"Sales Rec";"productivity",#N/A,FALSE,"Productivity Rec";"capitalspending",#N/A,FALSE,"Capital Spending"}
Name _Fill: #REF!
Name _Key1: #REF!
Name _Key2: #REF!
Name _Order1: 255
Name _Order2: 255
Name _Regression_X: #REF!
Name _Sort: #REF!
Name _Table1_In1: #REF!
Name _Table1_Out: #REF!
Name a: #REF!
Name abc.doc: {"'Income Statement'!$D$96:$E$101"}
Name ac: #REF!
Name ac: #REF!
Name AS2DocOpenMode: "AS2DocumentEdit"
Name AS2ReportLS: 1
Name AS2StaticLS: #REF!
Name AS2SyncStepLS: 0
Name AS2TickmarkLS: #REF!
Name AS2VersionLS: 300
Name BG_Del: 15
Name BG_Ins: 4
Name BG_Mod: 6
Name Code: #REF!
Name COL: #REF!
Name D: #REF!
Name data1: #REF!
Name data2: #REF!
Name data3: #REF!
Name ÐCompanyName: #REF!
Name Discount: #REF!
Name display_area_2: #REF!
Name ÐYesNoDropdown: #REF!
Name ENGEL: #REF!
Name FCode: #REF!
Name HiddenRows: #REF!
Name HTML_CodePage: 1252
Name HTML_Control: {"'Income Statement'!$D$96:$E$101"}
Name HTML_Description: "Profit & Loss Account"
Name HTML_Email: ""
Name HTML_Header: "Income Statement"
Name HTML_LastUpdate: "6/14/99"
Name HTML_LineAfter: TRUE
Name HTML_LineBefore: TRUE
Name HTML_Name: "Prakash Mishra"
Name HTML_OBDlg2: TRUE

Sheet Pivot
J1: Positions in Upload file
I2: Account
I3: GL Codes
H4: =MID(F4,8,LEN(F4)-7) -> #VALUE! | I4: {=_xludf.XLOOKUP(H4,'Billing sheet'!$CH$3:$CM$3,'Billing sheet'!$CH$2:$CM$2)} -> #NAME?
H5: =MID(F5,8,LEN(F5)-7) -> #VALUE! | I5: {=_xludf.XLOOKUP(H5,'Billing sheet'!$CH$3:$CM$3,'Billing sheet'!$CH$2:$CM$2)} -> #NAME?
H6: =MID(F6,8,LEN(F6)-7) -> #VALUE! | I6: {=_xludf.XLOOKUP(H6,'Billing sheet'!$CH$3:$CM$3,'Billing sheet'!$CH$2:$CM$2)} -> #NAME?
H7: =MID(F7,8,LEN(F7)-7) -> #VALUE! | I7: {=_xludf.XLOOKUP(H7,'Billing sheet'!$CH$3:$CM$3,'Billing sheet'!$CH$2:$CM$2)} -> #NAME?
H8: =MID(F8,8,LEN(F8)-7) -> #VALUE! | I8: {=_xludf.XLOOKUP(H8,'Billing sheet'!$CH$3:$CM$3,'Billing sheet'!$CH$2:$CM$2)} -> #NAME?
H9: =MID(F9,8,LEN(F9)-7) -> #VALUE! | I9: {=_xludf.XLOOKUP(H9,'Billing sheet'!$CH$3:$CM$3,'Billing sheet'!$CH$2:$CM$2)} -> #NAME?
H10: =MID(F10,8,LEN(F10)-7) -> #VALUE! | I10: {=_xludf.XLOOKUP(H10,'Billing sheet'!$CH$3:$CM$3,'Billing sheet'!$CH$2:$CM$2)} -> #NAME?
H11: =MID(F11,8,LEN(F11)-7) -> #VALUE! | I11: {=_xludf.XLOOKUP(H11,'Billing sheet'!$CH$3:$CM$3,'Billing sheet'!$CH$2:$CM$2)} -> #NAME?
H12: =MID(F12,8,LEN(F12)-7) -> #VALUE! | I12: {=_xludf.XLOOKUP(H12,'Billing sheet'!$CH$3:$CM$3,'Billing sheet'!$CH$2:$CM$2)} -> #NAME?
H13: =MID(F13,8,LEN(F13)-7) -> #VALUE! | I13: {=_xludf.XLOOKUP(H13,'Billing sheet'!$CH$3:$CM$3,'Billing sheet'!$CH$2:$CM$2)} -> #NAME?
H14: =MID(F14,8,LEN(F14)-7) -> #VALUE! | I14: {=_xludf.XLOOKUP(H14,'Billing sheet'!$CH$3:$CM$3,'Billing sheet'!$CH$2:$CM$2)} -> #NAME?
H15: =MID(F15,8,LEN(F15)-7) -> #VALUE! | I15: {=_xludf.XLOOKUP(H15,'Billing sheet'!$CH$3:$CM$3,'Billing sheet'!$CH$2:$CM$2)} -> #NAME?
... H8079: =MID(F8079,8,LEN(F8079)-7) -> #VALUE! | I8079: {=_xludf.XLOOKUP(H8079,'Billing sheet'!$CH$3:$CM$3,'Billing sheet'!$CH$2:$CM$2)} -> #NAME?
A8156: Billable Cost2 | B8156: Billable Cost
A8158: Invoice No. | B8158: Inv/ Bill No. | C8158: IC Code | D8158: Sum of Billable Cost
A8159: 30001333 | B8159: ATS/000250/25 | C8159: IN_RSM_GBS | D8159: 3475.27 | G8159: =D8159 -> 3475.27
A8160: 30001333 | B8160: ATS/000583/25 | C8160: IN_RSM_GBS | D8160: 3475.27 | G8160: =D8160 -> 3475.27
A8161: 30001333 | B8161: ATS/000914/25 | C8161: IN_RSM_GBS | D8161: 3475.27 | G8161: =D8161 -> 3475.27
A8162: 30001333 | B8162: ATS/001244/25 | C8162: IN_RSM_GBS | D8162: 3475.27 | G8162: =D8162 -> 3475.27
A8163: 30001333 | B8163: PGPLTGFEB1512526 | C8163: IN_RSM_GBS | D8163: 143514.19 | G8163: =D8163 -> 143514.19
A8164: 30001333 | B8164: PGPLTGFEB1502526 | C8164: IN_RSM_GBS | D8164: 137673.48 | G8164: =D8164 -> 137673.48
A8165: 30001333 | B8165: PGPLTGFEB1492526 | C8165: IN_RSM_GBS | D8165: 139163.1 | G8165: =D8165 -> 139163.1
A8166: 30001333 | B8166: CA1280002854 | C8166: IN_RSM_GBS | D8166: 20000 | G8166: =D8166 -> 20000
A8167: 30001333 | B8167: CD1210201355 | C8167: IN_RSM_GBS | D8167: 230467 | G8167: =D8167 -> 230467
A8168: 30001333 | B8168: CD1210201375 | C8168: IN_RSM_GBS | D8168: 9214 | G8168: =D8168 -> 9214
A8169: 30001333 | B8169: CA1280002827 | C8169: IN_RSM_GBS | D8169: 720.34 | G8169: =D8169 -> 720.34
A8170: 30001333 | B8170: 20258766 | C8170: IN_RSM_GBS | D8170: 3300 | G8170: =D8170 -> 3300
... A8181: 30001317 | B8181: RT95069628 | C8181: IN_MFM_L | D8181: 360000 | G8181: =D8181 -> 360000

Sheet Billing sheet
CC1: to be provided by Business team | CH1: GL Codes
O2: Recharge General Cost - Payroll | Q2: Recharge General Cost - Payroll | R2: Recharge General Cost - Retirals | S2: Recharge General Cost - Retirals | T2: Recharge General Cost - Payroll | U2: Recharge General Cost - Payroll | V2: Recharge General Cost - Payroll | W2: Recharge General Cost - Payroll | X2: Recharge General Cost - Payroll | Z2: Recharge General Cost - Leadership cost | AA2: Recharge General Cost - Manager | AC2: Recharge General Cost - Manager | AD2: Recharge General Cost - Manager | AE2: Recharge General Cost - Manager | AI2: Mark up | AJ2: Recharge General Cost - Desk Cost | AK2: Mark up | AW2: Data CC | AX2: Data CC | AY2: Data CC | AZ2: Data CC | BA2: Data CC | CC2: Ref Key 1 | CE2: Assignment Number (20) & Reference | CF2: Ref Key 3 | CG2: Ref Key 2 | CH2: 742234 | CI2: 742238 | CJ2: =CH2+1 -> 742235 | CK2: =CJ2+1 -> 742236 | CL2: =CK2+1 -> 742237 | CM2: 842028
A3: Workday ID | B3: EmpNo | C3: Name | D3: Date of joining | E3: Last working day | F3: Grade | G3: Capability Center | H3: ELT | I3: Location | J3: Type | K3: Billing | L3: Category of Billing | M3: Markup % | N3: Billing days | O3: Fixed CTC | P3: % of Bonus | Q3: Bonus 2026 | R3: Gratuity | S3: Leave Encashment | T3: PF admin Monthly | U3: EDLI Monthly | V3: Commision/ Joining bonus | W3: SBP Accrual | X3: Insurance | Y3: Total Payroll | Z3: Leadership cost | AA3: Managers desk fee | AB3: Payroll excluding Manager cost | AC3: Shiv Shankar's Cost | AD3: Anusha' Cost | AE3: Manager cost | AF3: Manager | AG3: Manager ID | AH3: Total Cost other than desk cost | AI3: TP on total cost | AJ3: Gross Desk Cost | AK3: TP on desk cost | AL3: Total billable amount | AM3: Client | AN3: Client for sumifs | AO3: Cost center | AP3: Legal Entity | AQ3: Classification | AR3: FTE count | AS3: Comments | AV3: Managers | AW3: Service Area | AX3: LOB | AY3: BU | AZ3: Cost center | BA3: Client | BB3: ** | BC3: LOP | BD3: Working_days | BE3: Days_Worked | BF3: NJoinee_ArrDays | BG3: Prv_Adj_Days | BH3: Prv_Arrear_Days | BI3: Billing days | BJ3: LOP | BK3: C/F LOP | BL3: Prv_Adj_Days | BM3: Billing adj | BN3: Closing LOP | BO3: LOP -1 month | BP3: LOP -2 Month | BQ3: LOP -3 Month | BR3: LOP -4 Month | BS3: LOP -5 Month | BT3: LOP -6 Month | BU3: LOP -7 Month | BV3: LOP -8 Month | BW3: LOP -9 Month | BX3: LOP -10 Month | BY3: LOP -11 Month | BZ3: Check | CB3: Billed/ Unbilled | CC3: IC Code | CD3: Customer Code | CE3: Invoice No. | CF3: EmpNo | CG3: Capability Center | CH3: Recharge General Cost - Payroll | CI3: Recharge General Cost - Manager | CJ3: Recharge General Cost - Leadership cost | CK3: Recharge General Cost - Desk Cost | CL3: Recharge General Cost - Retirals | CM3: Mark up | CO3: Diff
A4: W0008891 | B4: GCC5670 | C4: Yashwanth J | D4: 45978 | F4: L07 | G4: Finance Capability Center | H4: Abhishek Khurana | I4: IN - Hyderabad_HQ | K4: Unique | L4: Active | M4: 0.085 | N4: 28 | O4: 114840 | R4: 2760.5769 | S4: 1595 | T4: 287.1 | U4: 75 | W4: 0 | X4: 4460.3751 | Y4: 124018.05 | Z4: 5687.5 | AB4: 129705.55 | AH4: 129705.55 | AI4: 11024.972 | AJ4: 29700 | AK4: 2524.5 | AL4: 172955.02 | AM4: Randstad NV | AN4: Randstad NV | AO4: 1005310 | AP4: Randstad NV | AQ4: Billable | AR4: 1 | AW4: Talent Onboarding Solutions | AX4: GFKS | AY4: RGCC FSSC | AZ4: 1005310 | BC4: Considered | CB4: Accruals | CC4: NL_RSH | CD4: 60006 | CE4: #N/A | CF4: =A4 -> W0008891 | CG4: =G4 -> Finance Capability Center | CH4: =SUM(O4,Q4,T4:X4,) -> 119662.48 | CI4: =SUM(AA4,AE4) -> 0 | CJ4: =SUM(Z4) -> 5687.5 | CK4: =AJ4 -> 29700 | CL4: =SUM(R4:S4) -> 4355.5769 | CM4: =SUM(AI4,AK4) -> 13549.472 | CO4: =SUM(CH4:CM4,-AL4) -> 0
A5: W0005462 | B5: GCC4787 | C5: Namrata Gupta | D5: 45427 | F5: L05 | G5: BRAF | H5: Daco Team | I5: IN - Bangalore_HQ | K5: Unique | L5: Active | M5: 0.085 | N5: 28 | O5: 406333.33 | P5: 0.15 | Q5: 60950 | R5: 9767.6282 | S5: 5643.5185 | T5: 1015.8333 | U5: 75 | W5: 0 | X5: 5460.3751 | Y5: 489245.69 | Z5: 0 | AB5: 489245.69 | AH5: 489245.69 | AI5: 41585.884 | AJ5: 29700 | AK5: 2524.5 | AL5: 563056.07 | AM5: Randstad NV | AN5: Randstad NV | AO5: 1005220 | AP5: Randstad NV | AQ5: Billable | AR5: 1 | AW5: 0 | AX5: GFKS | AY5: 0 | AZ5: 1005220 | BC5: Considered | CB5: Accruals | CC5: NL_RSH | CD5: 60006 | CE5: #N/A | CF5: =A5 -> W0005462 | CG5: =G5 -> BRAF | CH5: =SUM(O5,Q5,T5:X5,) -> 473834.54 | CI5: =SUM(AA5,AE5) -> 0 | CJ5: =SUM(Z5) -> 0 | CK5: =AJ5 -> 29700 | CL5: =SUM(R5:S5) -> 15411.147 | CM5: =SUM(AI5,AK5) -> 44110.384 | CO5: =SUM(CH5:CM5,-AL5) -> 0
A6: W0005463 | B6: GCC4788 | C6: Kavitha Gunaseelan | D6: 45446 | F6: L04 | G6: BRAF | H6: Daco Team | I6: IN - Bangalore_HQ | K6: Unique | L6: Active | M6: 0.085 | N6: 28 | O6: 410166.67 | P6: 0.15 | Q6: 61525 | R6: 9859.7756 | S6: 5696.7593 | T6: 1025.4167 | U6: 75 | W6: 0 | X6: 5460.3751 | Y6: 493808.99 | Z6: 0 | AB6: 493808.99 | AH6: 493808.99 | AI6: 41973.764 | AJ6: 29700 | AK6: 2524.5 | AL6: 568007.26 | AM6: Randstad NV | AN6: Randstad NV | AO6: 1005220 | AP6: Randstad NV | AQ6: Billable | AR6: 1 | AW6: 0 | AX6: GFKS | AY6: 0 | AZ6: 1005220 | BC6: Considered | CB6: Accruals | CC6: NL_RSH | CD6: 60006 | CE6: #N/A | CF6: =A6 -> W0005463 | CG6: =G6 -> BRAF | CH6: =SUM(O6,Q6,T6:X6,) -> 478252.46 | CI6: =SUM(AA6,AE6) -> 0 | CJ6: =SUM(Z6) -> 0 | CK6: =AJ6 -> 29700 | CL6: =SUM(R6:S6) -> 15556.535 | CM6: =SUM(AI6,AK6) -> 44498.264 | CO6: =SUM(CH6:CM6,-AL6) -> 0
A7: W0005464 | B7: GCC4789 | C7: Rahul Kedia | D7: 45406 | F7: L04 | G7: BRAF | H7: Daco Team | I7: IN - Bangalore_HQ | K7: Unique | L7: Active | M7: 0.085 | N7: 28 | O7: 456000 | P7: 0.15 | Q7: 68400 | R7: 10961.538 | S7: 6333.3333 | T7: 1140 | U7: 75 | W7: 45076.596 | X7: 5460.3751 | Y7: 593446.84 | Z7: 0 | AB7: 593446.84 | AH7: 593446.84 | AI7: 50442.982 | AJ7: 29700 | AK7: 2524.5 | AL7: 676114.32 | AM7: Randstad NV | AN7: Randstad NV | AO7: 1005220 | AP7: Randstad NV | AQ7: Billable | AR7: 1 | AW7: 0 | AX7: GFKS | AY7: 0 | AZ7: 1005220 | BC7: Considered | CB7: Accruals | CC7: NL_RSH | CD7: 60006 | CE7: #N/A | CF7: =A7 -> W0005464 | CG7: =G7 -> BRAF | CH7: =SUM(O7,Q7,T7:X7,) -> 576151.97 | CI7: =SUM(AA7,AE7) -> 0 | CJ7: =SUM(Z7) -> 0 | CK7: =AJ7 -> 29700 | CL7: =SUM(R7:S7) -> 17294.872 | CM7: =SUM(AI7,AK7) -> 52967.482 | CO7: =SUM(CH7:CM7,-AL7) -> 0
A8: W0005465 | B8: GCC4790 | C8: Rohit Garg | D8: 45434 | F8: L06 | G8: BRAF | H8: Daco Team | I8: IN - Bangalore_HQ | K8: Unique | L8: Active | M8: 0.085 | N8: 28 | O8: 335666.67 | P8: 0.18 | Q8: 60420 | R8: 8068.9103 | S8: 4662.037 | T8: 839.16667 | U8: 75 | W8: 0 | X8: 4460.3751 | Y8: 414192.16 | Z8: 0 | AB8: 414192.16 | AH8: 414192.16 | AI8: 35206.333 | AJ8: 29700 | AK8: 2524.5 | AL8: 481622.99 | AM8: Randstad NV | AN8: Randstad NV | AO8: 1005220 | AP8: Randstad NV | AQ8: Billable | AR8: 1 | AW8: 0 | AX8: GFKS | AY8: 0 | AZ8: 1005220 | BC8: Considered | CB8: Accruals | CC8: NL_RSH | CD8: 60006 | CE8: #N/A | CF8: =A8 -> W0005465 | CG8: =G8 -> BRAF | CH8: =SUM(O8,Q8,T8:X8,) -> 401461.21 | CI8: =SUM(AA8,AE8) -> 0 | CJ8: =SUM(Z8) -> 0 | CK8: =AJ8 -> 29700 | CL8: =SUM(R8:S8) -> 12730.947 | CM8: =SUM(AI8,AK8) -> 37730.833 | CO8: =SUM(CH8:CM8,-AL8) -> 0
A9: W0005466 | B9: GCC4792 | C9: Devi Haridas | D9: 45460 | F9: L03 | G9: BRAF | H9: Daco Team | I9: IN - Bangalore_HQ | K9: Unique | L9: Active | M9: 0.085 | N9: 28 | O9: 700625 | P9: 0.15 | Q9: 105093.75 | R9: 16841.947 | S9: 9730.9028 | T9: 1751.5625 | U9: 75 | W9: 0 | X9: 5460.3751 | Y9: 839578.54 | Z9: 0 | AB9: 839578.54 | AH9: 839578.54 | AI9: 71364.176 | AJ9: 29700 | AK9: 2524.5 | AL9: 943167.21 | AM9: Randstad NV | AN9: Randstad NV | AO9: 1005220 | AP9: Randstad NV | AQ9: Billable | AR9: 1 | AW9: 0 | AX9: GFKS | AY9: Randstad Inhouse Netherlands | AZ9: 1005220 | BC9: Considered | CB9: Accruals | CC9: NL_RSH | CD9: 60006 | CE9: #N/A | CF9: =A9 -> W0005466 | CG9: =G9 -> BRAF | CH9: =SUM(O9,Q9,T9:X9,) -> 813005.69 | CI9: =SUM(AA9,AE9) -> 0 | CJ9: =SUM(Z9) -> 0 | CK9: =AJ9 -> 29700 | CL9: =SUM(R9:S9) -> 26572.85 | CM9: =SUM(AI9,AK9) -> 73888.676 | CO9: =SUM(CH9:CM9,-AL9) -> 0
A10: W0005467 | B10: GCC5492 | C10: Kaaviya Murali | D10: 45838 | F10: L05 | G10: BRAF | H10: Daco team | I10: IN - Bangalore_HQ | K10: Unique | L10: Active | M10: 0.085 | N10: 28 | O10: 303660 | P10: 0.15 | Q10: 45549 | R10: 7299.5192 | S10: 4217.5 | T10: 759.15 | U10: 75 | W10: 0 | X10: 5460.3751 | Y10: 367020.54 | Z10: 0 | AB10: 367020.54 | AH10: 367020.54 | AI10: 31196.746 | AJ10: 29700 | AK10: 2524.5 | AL10: 430441.79 | AM10: Randstad NV | AN10: Randstad NV | AO10: 1005220 | AP10: Randstad NV | AQ10: Billable | AR10: 1 | AW10: BRAF | AX10: RGCC HQ | AY10: BRAF | AZ10: 1005220 | BC10: Considered | CB10: Accruals | CC10: NL_RSH | CD10: 60006 | CE10: #N/A | CF10: =A10 -> W0005467 | CG10: =G10 -> BRAF | CH10: =SUM(O10,Q10,T10:X10,) -> 355503.53 | CI10: =SUM(AA10,AE10) -> 0 | CJ10: =SUM(Z10) -> 0 | CK10: =AJ10 -> 29700 | CL10: =SUM(R10:S10) -> 11517.019 | CM10: =SUM(AI10,AK10) -> 33721.246 | CO10: =SUM(CH10:CM10,-AL10) -> 0
A11: W0004060 | B11: GCC0008 | C11: Thejasvi Potta | D11: 40259 | F11: L08 | G11: HR Capability Center | H11: Shail Dasika | I11: IN - Hyderabad_HQ | K11: Unique | L11: Active | M11: 0.05 | N11: 28 | O11: 101126.58 | R11: 2430.9295 | S11: 1228.9699 | T11: 252.81667 | U11: 75 | W11: 0 | X11: 5460.3751 | Y11: 110574.67 | Z11: 12402.5 | AB11: 122977.17 | AE11: 33281 | AF11: Arpan Roy / Saurab | AG11: GCC5445 | AH11: 156258.17 | AI11: 7812.9087 | AJ11: 29700 | AK11: 1485 | AL11: 195256.08 | AM11: RUS | AN11: RUS | AO11: 35880 | AP11: Randstad Professional US LP, | AQ11: Billable | AR11: 1 | AW11: Sourcing | AX11: HRCC | AY11: HRCC | AZ11: 35880 | BC11: Considered | CB11: Billed | CC11: US_SAP_L | CD11: 60002 | CE11: 30001312 | CF11: =A11 -> W0004060 | CG11: HR | CH11: =SUM(O11,Q11,T11:X11,) -> 106914.78 | CI11: =SUM(AA11,AC11:AE11) -> 33281 | CJ11: =SUM(Z11) -> 12402.5 | CK11: =AJ11 -> 29700 | CL11: =SUM(R11:S11) -> 3659.8994 | CM11: =SUM(AI11,AK11) -> 9297.9087 | CO11: =SUM(CH11:CM11,-AL11) -> 0
A12: W0004061 | B12: GCC0044 | C12: Sunil Tangelapally | D12: 41699 | F12: L06 | G12: Talent Services Capability Center | H12: Ankur Sud | I12: IN - Hyderabad_HQ | K12: Unique | L12: Active | M12: 0.05 | N12: 28 | O12: 143905.42 | R12: 3339.0745 | S12: 1929.2431 | T12: 347.26375 | U12: 75 | W12: 0 | X12: 4460.3751 | Y12: 154056.37 | Z12: 4154.1667 | AB12: 158210.54 | AH12: 158210.54 | AI12: 7910.527 | AJ12: 29700 | AK12: 1485 | AL12: 197306.07 | AM12: Canada | AN12: Canada | AO12: 5151 38% + 2692 8% + 2653 15% + 2670 8% + 5436 8% + 2633 23% | AP12: Randstad Interim Inc. | AQ12: Billable | AR12: 1 | AW12: Recruiting(KR) | AX12: CANADA | AY12: PTS CDN RCD | AZ12: 5151 38% + 2692 8% + 2653 15% + 2670 8% + 5436 8% + 2633 23% | BC12: Considered | CB12: Billed | CC12: CA_RIC_SAP | CD12: 60005 | CE12: 30001334 | CF12: =A12 -> W0004061 | CG12: TS | CH12: =SUM(O12,Q12,T12:X12,) -> 148788.06 | CI12: =SUM(AA12,AC12:AE12) -> 0 | CJ12: =SUM(Z12) -> 4154.1667 | CK12: =AJ12 -> 29700 | CL12: =SUM(R12:S12) -> 5268.3176 | CM12: =SUM(AI12,AK12) -> 9395.527 | CO12: =SUM(CH12:CM12,-AL12) -> 0
A13: W0004062 | B13: GCC0048 | C13: Vaibhav Gupta | D13: 41750 | F13: L04 | G13: Talent Services Capability Center | H13: Ankur Sud | I13: IN - Hyderabad_HQ | K13: Unique | L13: Active | M13: 0.05 | N13: 28 | O13: 324424.67 | P13: 0.15 | Q13: 48663.7 | R13: 7678.4776 | S13: 0 | T13: 798.56167 | U13: 75 | W13: 8195.7448 | X13: 5460.3751 | Y13: 395296.53 | Z13: 4154.1667 | AB13: 399450.69 | AH13: 399450.69 | AI13: 19972.535 | AJ13: 29700 | AK13: 1485 | AL13: 450608.23 | AM13: RUS | AN13: RUS | AO13: 35801 | AP13: Randstad Professional US LP, | AQ13: Billable | AR13: 1 | AW13: Leadership | AX13: RD US | AY13: RGCC RD US | AZ13: 35801 | BC13: Considered | CB13: Billed | CC13: US_SAP_L | CD13: 60002 | CE13: 30001312 | CF13: =A13 -> W0004062 | CG13: TS | CH13: =SUM(O13,Q13,T13:X13,) -> 387618.05 | CI13: =SUM(AA13,AC13:AE13) -> 0 | CJ13: =SUM(Z13) -> 4154.1667 | CK13: =AJ13 -> 29700 | CL13: =SUM(R13:S13) -> 7678.4776 | CM13: =SUM(AI13,AK13) -> 21457.535 | CO13: =SUM(CH13:CM13,-AL13) -> 0
A14: W0004063 | B14: GCC0049 | C14: Shashank Gundu | D14: 41760 | F14: L05 | G14: Talent Services Capability Center | H14: Ankur Sud | I14: IN - Hyderabad_HQ | K14: Unique | L14: Active | M14: 0.05 | N14: 28 | O14: 212728.25 | Q14: 0 | R14: 4993.4696 | S14: 0 | T14: 519.32083 | U14: 75 | W14: 8195.7448 | X14: 4460.3751 | Y14: 230972.16 | Z14: 4154.1667 | AB14: 235126.33 | AH14: 235126.33 | AI14: 11756.316 | AJ14: 29700 | AK14: 1485 | AL14: 278067.64 | AM14: RUS | AN14: RUS | AO14: 35879 | AP14: Randstad Professional US LP, | AQ14: Billable | AR14: 1 | AW14: Leadership | AX14: RD US | AY14: Digital US - ConRtl | AZ14: 35879 | BC14: Considered | CB14: Billed | CC14: US_SAP_L | CD14: 60002 | CE14: 30001312 | CF14: =A14 -> W0004063 | CG14: TS | CH14: =SUM(O14,Q14,T14:X14,) -> 225978.69 | CI14: =SUM(AA14,AC14:AE14) -> 0 | CJ14: =SUM(Z14) -> 4154.1667 | CK14: =AJ14 -> 29700 | CL14: =SUM(R14:S14) -> 4993.4696 | CM14: =SUM(AI14,AK14) -> 13241.316 | CO14: =SUM(CH14:CM14,-AL14) -> 0
A15: W0004064 | B15: GCC0096 | C15: Praveen Sukkala | D15: 42051 | F15: L11 | G15: Talent Services Capability Center | H15: Ankur Sud | I15: IN - Hyderabad_HQ | K15: Unique | L15: Active | M15: 0.05 | N15: 28 | O15: 72550.167 | R15: 1743.9944 | S15: 125.95515 | T15: 181.37542 | U15: 75 | W15: 0 | X15: 4460.3751 | Y15: 79136.867 | Z15: 4154.1667 | AB15: 83291.033 | AH15: 83291.033 | AI15: 4164.5517 | AJ15: 29700 | AK15: 1485 | AL15: 118640.59 | AM15: Randstad Business solutions Ltd | AN15: Randstad Business solutions Ltd -Digital | AO15: B5500_OFFSH | AP15: Randstad Solutions Limited | AQ15: Billable | AR15: 1 | AW15: Recruiting(KR) | AX15: Randstad UK | AY15: RGCC RD UK | AZ15: B5500_OFFSH | BC15: Considered | CB15: Billed | CC15: UK_REB_L | CD15: 60009 | CE15: 30001337 | CF15: =A15 -> W0004064 | CG15: TS | CH15: =SUM(O15,Q15,T15:X15,) -> 77266.917 | CI15: =SUM(AA15,AC15:AE15) -> 0 | CJ15: =SUM(Z15) -> 4154.1667 | CK15: =AJ15 -> 29700 | CL15: =SUM(R15:S15) -> 1869.9495 | CM15: =SUM(AI15,AK15) -> 5649.5517 | CO15: =SUM(CH15:CM15,-AL15) -> 0
A16: W0004065 | B16: GCC0113 | C16: Sandeep Ejanthkar Ashok | D16: 42107 | E16: 46066 | F16: L09 | G16: Finance Capability Center | H16: Abhishek Khurana | I16: IN - Hyderabad_HQ | K16: Unique | L16: Exit emp | M16: 0.085 | N16: 13 | O16: 50655.622 | P16: 0.1 | Q16: 5065.5622 | R16: 2622.7043 | S16: 0 | T16: 272.76125 | U16: 75 | W16: 9220.2129 | X16: 4460.3751 | Y16: 72372.238 | Z16: 5687.5 | AB16: 78059.738 | AH16: 78059.738 | AI16: 6635.0777 | AJ16: 29700 | AK16: 2524.5 | AL16: 116919.32 | AM16: RGCC HQ | AN16: RGCC Hyd | AO16: RGCC-HQ | AP16: RGCC Hyd | AQ16: Non Billable | AR16: 1 | AW16: Data Analytics | AX16: RGCC HQ | AY16: RGCC HQ | AZ16: RGCC-HQ | BC16: Considered | CB16: Unbillled
A17: W0004067 | B17: GCC0120 | C17: Kishore Banda | D17: 42114 | F17: L09 | G17: Talent Services Capability Center | H17: Ankur Sud | I17: IN - Hyderabad_HQ | K17: Unique | L17: Active | M17: 0.05 | N17: 28 | O17: 100392.08 | R17: 2293.0809 | S17: 298.10052 | T17: 238.48042 | U17: 75 | W17: 6146.8086 | X17: 4460.3751 | Y17: 113903.93 | Z17: 4154.1667 | AB17: 118058.1 | AH17: 118058.1 | AI17: 5902.9048 | AJ17: 29700 | AK17: 1485 | AL17: 155146 | AM17: RUS | AN17: RUS | AO17: 35875 | AP17: Randstad Professional US LP, | AQ17: Billable | AR17: 1 | AW17: Recruiting(KR) | AX17: RD US | AY17: Digital US - BFSI | AZ17: 35875 | BC17: Considered | CB17: Billed | CC17: US_SAP_L | CD17: 60002 | CE17: 30001312 | CF17: =A17 -> W0004067 | CG17: TS | CH17: =SUM(O17,Q17,T17:X17,) -> 111312.75 | CI17: =SUM(AA17,AC17:AE17) -> 0 | CJ17: =SUM(Z17) -> 4154.1667 | CK17: =AJ17 -> 29700 | CL17: =SUM(R17:S17) -> 2591.1815 | CM17: =SUM(AI17,AK17) -> 7387.9048 | CO17: =SUM(CH17:CM17,-AL17) -> 0
A18: W0004068 | B18: GCC0170 | C18: Vaishnavi Kolluru | D18: 42261 | F18: L10 | G18: HR Capability Center | H18: Shail Dasika | I18: IN - Hyderabad_HQ | K18: Unique | L18: Active | M18: 0.05 | N18: 28 | O18: 66747.583 | R18: 1604.5112 | S18: 463.52546 | T18: 166.86917 | U18: 75 | W18: 2048.9362 | X18: 4460.3751 | Y18: 75566.801 | Z18: 12402.5 | AB18: 87969.301 | AE18: 33281 | AF18: Arpan Roy / Saurab | AG18: GCC5445 | AH18: 121250.3 | AI18: 6062.515 | AJ18: 29700 | AK18: 1485 | AL18: 158497.82 | AM18: RUS | AN18: RUS | AO18: 90208 | AP18: Randstad Professional US LP, | AQ18: Billable | AR18: 1 | AW18: Sourcing | AX18: HRCC | AY18: HRCC | AZ18: 90208 | BC18: Considered | CB18: Billed | CC18: US_SAP_L | CD18: 60002 | CE18: 30001312 | CF18: =A18 -> W0004068 | CG18: HR | CH18: =SUM(O18,Q18,T18:X18,) -> 73498.764 | CI18: =SUM(AA18,AC18:AE18) -> 33281 | CJ18: =SUM(Z18) -> 12402.5 | CK18: =AJ18 -> 29700 | CL18: =SUM(R18:S18) -> 2068.0367 | CM18: =SUM(AI18,AK18) -> 7547.515 | CO18: =SUM(CH18:CM18,-AL18) -> 0
A19: W0004069 | B19: GCC0204 | C19: Praveen Pallerlamudi | D19: 42361 | F19: L04 | G19: Talent Services Capability Center | H19: Aqueel Merchant | I19: IN - Hyderabad_HQ | K19: Managers | L19: Active | M19: 0.05 | N19: 28 | O19: 425053.92 | P19: 0.22 | Q19: 93511.862 | R19: 10217.644 | S19: 0 | T19: 1062.635 | U19: 75 | W19: 28685.107 | X19: 5460.3751 | Y19: 564066.54 | Z19: 4154.1667 | AA19: 29700 | AB19: 597920.71 | AE19: -597920.71 | AH19: 0 | AI19: 0 | AK19: 0 | AL19: 0 | AM19: Randstad Business solutions Ltd +Randstad Business solutions Ltd + Randstad Business solutions Ltd + Randstad Business solutions Ltd + Pareto Law UK Limited + RUS + RUS + RUS + RUS + Canada + Canada + RGCC Australia + RGCC Australia + RGCC Australia + Randstad Inhouse Netherland + Yacht Netherlands + Tempo Netherlands + Tempo Netherlands | AN19: Managers cost | AO19: P1000_OFFSH 8% + C9000_OFFSH 8% + D9503_OFFSH 8% + E9000_OFFSH 8% + CSEX_OFFSH 8% + 35801 31% + 38542 4% + 12021 4% + 19449 4% + 5151 5% + 2933 5% + 5185 1% + 7826 0.5% + 7071 0.5% + 7178485 2% + 1951 1% + 1502348 RRC TTPM 1% + 150149556G1495 1% | AP19: RGCC Hyd | AQ19: Non Billable -Managers | AR19: 1 | AW19: Leadership | AX19: RT | AY19: RGCC RT East | AZ19: P1000_OFFSH 8% + C9000_OFFSH 8% + D9503_OFFSH 8% + E9000_OFFSH 8% + CSEX_OFFSH 8% + 35801 31% + 38542 4% + 12021 4% + 19449 4% + 5151 5% + 2933 5% + 5185 1% + 7826 0.5% + 7071 0.5% + 7178485 2% + 1951 1% + 1502348 RRC TTPM 1% + 150149556G1495 1% | BC19: Considered | CB19: Unbillled
A20: W0004070 | B20: GCC0233 | C20: Purna S | D20: 42500 | F20: L09 | G20: Enablers-GCC | H20: Aqueel Merchant | I20: IN - Hyderabad_HQ | K20: Unique | L20: Active | M20: 0 | N20: 28 | O20: 101403.5 | P20: 0.1 | Q20: 10140.35 | R20: 2437.5841 | S20: 316.88594 | T20: 253.50875 | U20: 75 | W20: 8099.4448 | X20: 4460.3751 | Y20: 127186.65 | Z20: 0 | AB20: 127186.65 | AH20: 127186.65 | AI20: 0 | AJ20: 29700 | AK20: 0 | AL20: 156886.65 | AM20: RGCC HQ | AN20: RGCC Hyd | AO20: RGCC-HQ | AP20: RGCC Hyd | AQ20: Non Billable | AR20: 1 | AW20: Internal Communication | AX20: RGCC HQ | AY20: RGCC HQ | AZ20: RGCC-HQ | BC20: Considered | CB20: Unbillled
A21: W0004071 | B21: GCC0234 | C21: Sri Harsha Satyavaram | D21: 42501 | F21: L07 | G21: Talent Services Capability Center | H21: Ankur Sud | I21: IN - Hyderabad_HQ | K21: Unique | L21: Active | M21: 0.05 | N21: 28 | O21: 155968.58 | R21: 3629.0545 | S21: 0 | T21: 377.42167 | U21: 75 | W21: 0 | X21: 4460.3751 | Y21: 164510.43 | Z21: 4154.1667 | AB21: 168664.6 | AH21: 168664.6 | AI21: 8433.2301 | AJ21: 29700 | AK21: 1485 | AL21: 208282.83 | AM21: RUS | AN21: RUS | AO21: 35070 | AP21: Randstad Professional US LP, | AQ21: Billable | AR21: 1 | AW21: Operations | AX21: RD US | AY21: Digital US - RITS - TPV | AZ21: 35070 | BC21: Considered | CB21: Billed | CC21: US_SAP_L | CD21: 60002 | CE21: 30001312 | CF21: =A21 -> W0004071 | CG21: TS | CH21: =SUM(O21,Q21,T21:X21,) -> 160881.38 | CI21: =SUM(AA21,AC21:AE21) -> 0 | CJ21: =SUM(Z21) -> 4154.1667 | CK21: =AJ21 -> 29700 | CL21: =SUM(R21:S21) -> 3629.0545 | CM21: =SUM(AI21,AK21) -> 9918.2301 | CO21: =SUM(CH21:CM21,-AL21) -> 0
A22: W0005123 | B22: GCC0317 | C22: Venkata Kishore G.K. | D22: 42730 | F22: L07 | G22: Talent Services Capability Center | H22: Ankur Sud | I22: IN - Hyderabad_HQ | K22: Unique | L22: Active | M22: 0.05 | N22: 28 | O22: 113340.17 | R22: 2604.3309 | S22: 1090.9253 | T22: 270.85042 | U22: 75 | W22: 10433.183 | X22: 4460.3751 | Y22: 132274.83 | Z22: 4154.1667 | AB22: 136429 | AH22: 136429 | AI22: 6821.4499 | AJ22: 29700 | AK22: 1485 | AL22: 174435.45 | AM22: RUS | AN22: RUS | AO22: 34732 | AP22: Randstad Professional US LP, | AQ22: Billable | AR22: 1 | AW22: Leadership | AX22: RE | AY22: RGCC OTS US ENG | AZ22: 34732 | BC22: Considered | CB22: Billed | CC22: US_SAP_L | CD22: 60002 | CE22: 30001312 | CF22: =A22 -> W0005123 | CG22: TS | CH22: =SUM(O22,Q22,T22:X22,) -> 128579.58 | CI22: =SUM(AA22,AC22:AE22) -> 0 | CJ22: =SUM(Z22) -> 4154.1667 | CK22: =AJ22 -> 29700 | CL22: =SUM(R22:S22) -> 3695.2562 | CM22: =SUM(AI22,AK22) -> 8306.4499 | CO22: =SUM(CH22:CM22,-AL22) -> 0
A23: W0004072 | B23: GCC0331 | C23: Sinduja Kola | D23: 42758 | F23: L11 | G23: HR Capability Center | H23: Shail Dasika | I23: IN - Hyderabad_HQ | K23: Unique | L23: Active | M23: 0.05 | N23: 28 | O23: 54167.583 | R23: 1302.1074 | S23: 752.3287 | T23: 135.41917 | U23: 75 | W23: 5548.5192 | X23: 4460.3751 | Y23: 66441.333 | Z23: 12402.5 | AB23: 78843.833 | AH23: 78843.833 | AI23: 3942.1916 | AJ23: 29700 | AK23: 1485 | AL23: 113971.02 | AM23: RUS | AN23: RUS | AO23: 90208 | AP23: Randstad Professional US LP, | AQ23: Billable | AR23: 1 | AW23: Sourcing | AX23: HRCC | AY23: HRCC | AZ23: 90208 | BC23: Considered | CB23: Billed | CC23: US_SAP_L | CD23: 60002 | CE23: 30001312 | CF23: =A23 -> W0004072 | CG23: HR | CH23: =SUM(O23,Q23,T23:X23,) -> 64386.897 | CI23: =SUM(AA23,AC23:AE23) -> 0 | CJ23: =SUM(Z23) -> 12402.5 | CK23: =AJ23 -> 29700 | CL23: =SUM(R23:S23) -> 2054.4361 | CM23: =SUM(AI23,AK23) -> 5427.1916 | CO23: =SUM(CH23:CM23,-AL23) -> 0
A24: W0004073 | B24: GCC0358 | C24: Sabitha Kumari | D24: 42828 | F24: L09 | G24: Talent Services Capability Center | H24: Ankur Sud | I24: IN - Hyderabad_HQ | K24: Unique | L24: Active | M24: 0.05 | N24: 28 | O24: 93143.25 | R24: 2118.8301 | S24: 0 | T24: 220.35833 | U24: 75 | W24: 2868.5107 | X24: 4460.3751 | Y24: 102886.32 | Z24: 4154.1667 | AB24: 107040.49 | AH24: 107040.49 | AI24: 5352.0245 | AJ24: 29700 | AK24: 1485 | AL24: 143577.52 | AM24: Randstad Australia | AN24: RGCC Australia | AO24: 2750 | AP24: Randstad Pty Ltd. | AQ24: Billable | AR24: 1 | AW24: Recruiting(KR) | AX24: RGCC Australia | AY24: RP - Business Support Australia | AZ24: 2750 | BC24: Considered | CB24: Billed | CC24: AU_RAN_L | CD24: 60014 | CE24: 30001338 | CF24: =A24 -> W0004073 | CG24: TS | CH24: =SUM(O24,Q24,T24:X24,) -> 100767.49 | CI24: =SUM(AA24,AC24:AE24) -> 0 | CJ24: =SUM(Z24) -> 4154.1667 | CK24: =AJ24 -> 29700 | CL24: =SUM(R24:S24) -> 2118.8301 | CM24: =SUM(AI24,AK24) -> 6837.0245 | CO24: =SUM(CH24:CM24,-AL24) -> 0
A25: W0004074 | B25: GCC0394 | C25: Naresh Reddy | D25: 42908 | F25: L09 | G25: Talent Services Capability Center | H25: Ankur Sud | I25: IN - Hyderabad_HQ | K25: Unique | L25: Active | M25: 0.05 | N25: 28 | O25: 92424 | R25: 2101.5385 | S25: 1214.2222 | T25: 218.56 | U25: 75 | W25: 0 | X25: 4460.3751 | Y25: 100493.7 | Z25: 4154.1667 | AB25: 104647.86 | AH25: 104647.86 | AI25: 5232.3931 | AJ25: 29700 | AK25: 1485 | AL25: 141065.26 | AM25: RUS | AN25: RUS | AO25: 35887 | AP25: Randstad Professional US LP, | AQ25: Billable | AR25: 1 | AW25: Recruiting(KR) | AX25: RD US | AY25: Digital US - TMT- AAMDP | AZ25: 35887 | BC25: Considered | CB25: Billed | CC25: US_SAP_L | CD25: 60002 | CE25: 30001312 | CF25: =A25 -> W0004074 | CG25: TS | CH25: =SUM(O25,Q25,T25:X25,) -> 97177.935 | CI25: =SUM(AA25,AC25:AE25) -> 0 | CJ25: =SUM(Z25) -> 4154.1667 | CK25: =AJ25 -> 29700 | CL25: =SUM(R25:S25) -> 3315.7607 | CM25: =SUM(AI25,AK25) -> 6717.3931 | CO25: =SUM(CH25:CM25,-AL25) -> 0
A26: W0004075 | B26: GCC0396 | C26: Srikakula Anusha | D26: 42919 | F26: L08 | G26: Finance Capability Center | H26: Abhishek Khurana | I26: IN - Hyderabad_HQ | K26: Unique | L26: Active | M26: 0.085 | N26: 28 | O26: 82289.833 | R26: 1857.9287 | S26: 0 | T26: 193.22458 | U26: 75 | W26: 0 | X26: 4460.3751 | Y26: 88876.362 | Z26: 5687.5 | AB26: 94563.862 | AE26: 7641.9688 | AF26: Deepak Sharma | AG26: GCC1133 | AH26: 102205.83 | AI26: 8687.4956 | AJ26: 29700 | AK26: 2524.5 | AL26: 143117.83 | AM26: Canada | AN26: Canada | AO26: 2933 | AP26: Randstad Interim Inc. | AQ26: Billable | AR26: 1 | AW26: VMS Support and Admin | AX26: CANADA | AY26: RGCC Canada | AZ26: 2933 | BC26: Considered | CB26: Billed | CC26: CA_RIC_SAP | CD26: 60005 | CE26: 30001334 | CF26: =A26 -> W0004075 | CG26: Fin | CH26: =SUM(O26,Q26,T26:X26,) -> 87018.433 | CI26: =SUM(AA26,AC26:AE26) -> 7641.9688 | CJ26: =SUM(Z26) -> 5687.5 | CK26: =AJ26 -> 29700 | CL26: =SUM(R26:S26) -> 1857.9287 | CM26: =SUM(AI26,AK26) -> 11211.996 | CO26: =SUM(CH26:CM26,-AL26) -> 0
A27: W0004076 | B27: GCC0408 | C27: Vinay Malka | D27: 42984 | F27: L06 | G27: Talent Services Capability Center | H27: Ankur Sud | I27: IN - Hyderabad_HQ | K27: Unique | L27: Active | M27: 0.05 | N27: 28 | O27: 157585.08 | R27: 3667.9127 | S27: 2119.2384 | T27: 381.46292 | U27: 75 | W27: 8195.7448 | X27: 4460.3751 | Y27: 176484.82 | Z27: 4154.1667 | AB27: 180638.98 | AH27: 180638.98 | AI27: 9031.9492 | AJ27: 29700 | AK27: 1485 | AL27: 220855.93 | AM27: RUS | AN27: RUS | AO27: 35887 | AP27: Randstad Professional US LP, | AQ27: Billable | AR27: 1 | AW27: Leadership | AX27: RD US | AY27: Digital US - TMT- AAMDP | AZ27: 35887 | BC27: Considered | CB27: Billed | CC27: US_SAP_L | CD27: 60002 | CE27: 30001312 | CF27: =A27 -> W0004076 | CG27: TS | CH27: =SUM(O27,Q27,T27:X27,) -> 170697.67 | CI27: =SUM(AA27,AC27:AE27) -> 0 | CJ27: =SUM(Z27) -> 4154.1667 | CK27: =AJ27 -> 29700 | CL27: =SUM(R27:S27) -> 5787.1511 | CM27: =SUM(AI27,AK27) -> 10516.949 | CO27: =SUM(CH27:CM27,-AL27) -> 0
A28: W0004077 | B28: GCC0422 | C28: Abhinand Kumar | D28: 43026 | F28: L07 | G28: Talent Services Capability Center | H28: Ankur Sud | I28: IN - Hyderabad_HQ | K28: Unique | L28: Active | M28: 0.05 | N28: 28 | O28: 105669.75 | R28: 2419.9479 | S28: 0 | T28: 251.67458 | U28: 75 | W28: 10314.345 | X28: 4460.3751 | Y28: 123191.09 | Z28: 4154.1667 | AB28: 127345.26 | AH28: 127345.26 | AI28: 6367.263 | AJ28: 29700 | AK28: 1485 | AL28: 164897.52 | AM28: RUS | AN28: RUS | AO28: 12021: 20% 19449: 20% 89079: 30% 14411: 10% 17036: 10% | AP28: Randstad Professional US LP, | AQ28: Billable | AR28: 1 | AW28: Recruiting(KR) | AX28: RP | AY28: PTS US Biz Services | AZ28: 12021: 20% 19449: 20% 89079: 30% 14411: 10% 17036: 10% | BC28: Considered | CB28: Billed | CC28: US_SAP_L | CD28: 60002 | CE28: 30001312 | CF28: =A28 -> W0004077 | CG28: TS | CH28: =SUM(O28,Q28,T28:X28,) -> 120771.14 | CI28: =SUM(AA28,AC28:AE28) -> 0 | CJ28: =SUM(Z28) -> 4154.1667 | CK28: =AJ28 -> 29700 | CL28: =SUM(R28:S28) -> 2419.9479 | CM28: =SUM(AI28,AK28) -> 7852.263 | CO28: =SUM(CH28:CM28,-AL28) -> 0
A29: W0004078 | B29: GCC0431 | C29: Bhavani Guru Prasad | D29: 43040 | F29: L08 | G29: Business Operations and Service Delivery | H29: Rishi Kumar Gupta | I29: IN - Hyderabad_HQ | K29: Unique | L29: Active | M29: 0.085 | N29: 28 | O29: 109289.67 | R29: 2506.9631 | S29: 1448.4676 | T29: 260.72417 | U29: 75 | W29: 0 | X29: 4460.3751 | Y29: 118041.2 | Z29: 23570.833 | AB29: 141612.03 | AH29: 141612.03 | AI29: 12037.023 | AJ29: 29700 | AK29: 2524.5 | AL29: 185873.55 | AM29: RUS | AN29: RUS | AO29: 90020 | AP29: Randstad Professional US LP, | AQ29: Billable | AR29: 1 | AW29: Legal | AX29: RUS | AY29: RGCC RUS RBE | AZ29: 90020 | BC29: Considered | CB29: Billed | CC29: US_SAP_L | CD29: 60002 | CE29: 30001312 | CF29: =A29 -> W0004078 | CG29: BO & SD | CH29: =SUM(O29,Q29,T29:X29,) -> 114085.77 | CI29: =SUM(AA29,AC29:AE29) -> 0 | CJ29: =SUM(Z29) -> 23570.833 | CK29: =AJ29 -> 29700 | CL29: =SUM(R29:S29) -> 3955.4307 | CM29: =SUM(AI29,AK29) -> 14561.523 | CO29: =SUM(CH29:CM29,-AL29) -> 0
A30: W0004079 | B30: GCC0444 | C30: Srinivas Jogiparthy | D30: 43059 | F30: L09 | G30: Talent Services Capability Center | H30: Ankur Sud | I30: IN - Hyderabad_HQ | K30: Unique | L30: Active | M30: 0.05 | N30: 28 | O30: 66505.75 | R30: 1478.5056 | S30: 234.91811 | T30: 153.76458 | U30: 75 | W30: 5196.1022 | X30: 4460.3751 | Y30: 78104.416 | Z30: 4154.1667 | AB30: 82258.582 | AH30: 82258.582 | AI30: 4112.9291 | AJ30: 29700 | AK30: 1485 | AL30: 117556.51 | AM30: RUS | AN30: RUS | AO30: 34732 | AP30: Randstad Professional US LP, | AQ30: Billable | AR30: 1 | AW30: Recruiting(KR) | AX30: RE | AY30: RGCC OTS US ENG | AZ30: 34732 | BC30: Considered | CB30: Billed | CC30: US_SAP_L | CD30: 60002 | CE30: 30001312 | CF30: =A30 -> W0004079 | CG30: TS | CH30: =SUM(O30,Q30,T30:X30,) -> 76390.992 | CI30: =SUM(AA30,AC30:AE30) -> 0 | CJ30: =SUM(Z30) -> 4154.1667 | CK30: =AJ30 -> 29700 | CL30: =SUM(R30:S30) -> 1713.4237 | CM30: =SUM(AI30,AK30) -> 5597.9291 | CO30: =SUM(CH30:CM30,-AL30) -> 0
A31: W0004080 | B31: GCC0446 | C31: Anirudh Sangulugari | D31: 43066 | F31: L06 | G31: Talent Services Capability Center | H31: Ankur Sud | I31: IN - Hyderabad_HQ | K31: Unique | L31: Active | M31: 0.05 | N31: 28 | O31: 179016.17 | R31: 4183.0809 | S31: 0 | T31: 435.04042 | U31: 75 | W31: 16758.249 | X31: 4460.3751 | Y31: 204927.91 | Z31: 4154.1667 | AB31: 209082.08 | AH31: 209082.08 | AI31: 10454.104 | AJ31: 29700 | AK31: 1485 | AL31: 250721.18 | AM31: Canada | AN31: Canada | AO31: 2933 | AP31: Randstad Interim Inc. | AQ31: Billable | AR31: 1 | AW31: Leadership | AX31: CANADA | AY31: RGCC RD Canada | AZ31: 2933 | BC31: Considered | CB31: Billed | CC31: CA_RIC_SAP | CD31: 60005 | CE31: 30001334 | CF31: =A31 -> W0004080 | CG31: TS | CH31: =SUM(O31,Q31,T31:X31,) -> 200744.83 | CI31: =SUM(AA31,AC31:AE31) -> 0 | CJ31: =SUM(Z31) -> 4154.1667 | CK31: =AJ31 -> 29700 | CL31: =SUM(R31:S31) -> 4183.0809 | CM31: =SUM(AI31,AK31) -> 11939.104 | CO31: =SUM(CH31:CM31,-AL31) -> 0
A32: W0005291 | B32: GCC0471 | C32: Sai Telkar | D32: 43143 | F32: L07 | G32: Talent Services Capability Center | H32: Ankur Sud | I32: IN - Hyderabad_HQ | K32: Unique | L32: Active | M32: 0.05 | N32: 28 | O32: 103024.58 | R32: 2356.3622 | S32: 0 | T32: 245.06167 | U32: 75 | W32: 9439.449 | X32: 4460.3751 | Y32: 119600.83 | Z32: 4154.1667 | AB32: 123755 | AH32: 123755 | AI32: 6187.7499 | AJ32: 29700 | AK32: 1485 | AL32: 161127.75 | AM32: RUS | AN32: RUS | AO32: 35875 | AP32: Randstad Professional US LP, | AQ32: Billable | AR32: 1 | AW32: Leadership | AX32: RD US | AY32: Digital US - BFSI | AZ32: 35875 | BC32: Considered | CB32: Billed | CC32: US_SAP_L | CD32: 60002 | CE32: 30001312 | CF32: =A32 -> W0005291 | CG32: TS | CH32: =SUM(O32,Q32,T32:X32,) -> 117244.47 | CI32: =SUM(AA32,AC32:AE32) -> 0 | CJ32: =SUM(Z32) -> 4154.1667 | CK32: =AJ32 -> 29700 | CL32: =SUM(R32:S32) -> 2356.3622 | CM32: =SUM(AI32,AK32) -> 7672.7499 | CO32: =SUM(CH32:CM32,-AL32) -> 0
A33: W0004081 | B33: GCC0485 | C33: Kabirunnisa Begum | D33: 43164 | F33: L10 | G33: Talent Services Capability Center | H33: Ankur Sud | I33: IN - Hyderabad_HQ | K33: Unique | L33: Active | M33: 0.05 | N33: 28 | O33: 69831.75 | R33: 1558.4575 | S33: 0 | T33: 162.07958 | U33: 75 | W33: 0 | X33: 4460.3751 | Y33: 76087.662 | Z33: 4154.1667 | AB33: 80241.829 | AH33: 80241.829 | AI33: 4012.0914 | AJ33: 29700 | AK33: 1485 | AL33: 115438.92 | AM33: RUS | AN33: RUS | AO33: 35879 | AP33: Randstad Professional US LP, | AQ33: Billable | AR33: 1 | AW33: Recruiting(KR) | AX33: RD US | AY33: Digital US - ConRtl | AZ33: 35879 | BC33: Considered | CB33: Billed | CC33: US_SAP_L | CD33: 60002 | CE33: 30001312 | CF33: =A33 -> W0004081 | CG33: TS | CH33: =SUM(O33,Q33,T33:X33,) -> 74529.205 | CI33: =SUM(AA33,AC33:AE33) -> 0 | CJ33: =SUM(Z33) -> 4154.1667 | CK33: =AJ33 -> 29700 | CL33: =SUM(R33:S33) -> 1558.4575 | CM33: =SUM(AI33,AK33) -> 5497.0914 | CO33: =SUM(CH33:CM33,-AL33) -> 0
A34: W0005293 | B34: GCC0519 | C34: Divya Janmohan (On Leave) | D34: 43258 | F34: L10 | G34: Talent Services Capability Center | H34: Ankur Sud | I34: IN - Hyderabad_HQ | K34: Unique | L34: Active | M34: 0.05 | N34: 28 | O34: 54844.917 | R34: 1318.3894 | S34: 0 | T34: 137.1125 | U34: 75 | W34: 0 | X34: 4460.3751 | Y34: 60835.794 | Z34: 4154.1667 | AB34: 64989.96 | AE34: 4671.4236 | AF34: Praveen Pallerlamudi | AG34: GCC0204 | AH34: 69661.384 | AI34: 3483.0692 | AJ34: 29700 | AK34: 1485 | AL34: 104329.45 | AM34: Randstad Business solutions Ltd | AN34: Randstad Business solutions Ltd | AO34: C1182_OFFSH | AP34: Randstad Solutions Limited | AQ34: Billable | AR34: 1 | AW34: Recruiting(KR) | AX34: Randstad UK | AY34: PTS UK Care RSW | AZ34: C1182_OFFSH | BC34: Considered | CB34: Billed | CC34: UK_REB_L | CD34: 60009 | CE34: 30001339 | CF34: =A34 -> W0005293 | CG34: TS | CH34: =SUM(O34,Q34,T34:X34,) -> 59517.404 | CI34: =SUM(AA34,AC34:AE34) -> 4671.4236 | CJ34: =SUM(Z34) -> 4154.1667 | CK34: =AJ34 -> 29700 | CL34: =SUM(R34:S34) -> 1318.3894 | CM34: =SUM(AI34,AK34) -> 4968.0692 | CO34: =SUM(CH34:CM34,-AL34) -> 0
A35: W0005294 | B35: GCC0523 | C35: Snigdha Thakker | D35: 43262 | F35: L08 | G35: Finance Capability Center | H35: Abhishek Khurana | I35: IN - Hyderabad_HQ | K35: Unique | L35: Active | M35: 0.085 | N35: 28 | O35: 97732.167 | R35: 2229.1386 | S35: 0 | T35: 231.83042 | U35: 75 | W35: 0 | X35: 4460.3751 | Y35: 104728.51 | Z35: 5687.5 | AB35: 110416.01 | AE35: 6263.256 | AF35: Poojan Gandhi | AG35: GCC1254 | AH35: 116679.27 | AI35: 9917.7377 | AJ35: 29700 | AK35: 2524.5 | AL35: 158821.5 | AM35: RUS | AN35: RUS | AO35: 90349 | AP35: Randstad Professional US LP, | AQ35: Billable | AR35: 1 | AW35: Audit & Assurance | AX35: RUS | AY35: RGCC RUS RBE | AZ35: 90349 | BC35: Considered | CB35: Billed | CC35: US_SAP_L | CD35: 60002 | CE35: 30001312 | CF35: =A35 -> W0005294 | CG35: Fin | CH35: =SUM(O35,Q35,T35:X35,) -> 102499.37 | CI35: =SUM(AA35,AC35:AE35) -> 6263.256 | CJ35: =SUM(Z35) -> 5687.5 | CK35: =AJ35 -> 29700 | CL35: =SUM(R35:S35) -> 2229.1386 | CM35: =SUM(AI35,AK35) -> 12442.238 | CO35: =SUM(CH35:CM35,-AL35) -> 0
A36: W0005124 | B36: GCC0552 | C36: Fatima Khatoon | D36: 43305 | F36: L06 | G36: Talent Services Capability Center | H36: Ankur Sud | I36: IN - Hyderabad_HQ | K36: Unique | L36: Active | M36: 0.05 | N36: 28 | O36: 93910.75 | R36: 2137.2796 | S36: 0 | T36: 222.27708 | U36: 75 | W36: 0 | X36: 4460.3751 | Y36: 100805.68 | Z36: 4154.1667 | AB36: 104959.85 | AH36: 104959.85 | AI36: 5247.9924 | AJ36: 29700 | AK36: 1485 | AL36: 141392.84 | AM36: RGCC Australia | AN36: RGCC Australia | AO36: 5220 | AP36: Randstad Pty Ltd. | AQ36: Billable | AR36: 1 | AW36: Leadership | AX36: RGCC Australia | AY36: RGCC PTS AUS Education | AZ36: 5220 | BC36: Considered | CB36: Billed | CC36: AU_RAN_L | CD36: 60014 | CE36: 30001338 | CF36: =A36 -> W0005124 | CG36: TS | CH36: =SUM(O36,Q36,T36:X36,) -> 98668.402 | CI36: =SUM(AA36,AC36:AE36) -> 0 | CJ36: =SUM(Z36) -> 4154.1667 | CK36: =AJ36 -> 29700 | CL36: =SUM(R36:S36) -> 2137.2796 | CM36: =SUM(AI36,AK36) -> 6732.9924 | CO36: =SUM(CH36:CM36,-AL36) -> 0
A37: W0004083 | B37: GCC0598 | C37: Jagadish Elipilla | D37: 43325 | F37: L08 | G37: Finance Capability Center | H37: Abhishek Khurana | I37: IN - Hyderabad_HQ | K37: Unique | L37: Active | M37: 0.085 | N37: 28 | O37: 103358.08 | R37: 2364.379 | S37: 1366.0856 | T37: 245.89542 | U37: 75 | W37: 0 | X37: 4460.3751 | Y37: 111869.82 | Z37: 5687.5 | AB37: 117557.32 | AE37: 7641.9688 | AF37: Deepak Sharma | AG37: GCC1133 | AH37: 125199.29 | AI37: 10641.939 | AJ37: 29700 | AK37: 2524.5 | AL37: 168065.73 | AM37: RUS | AN37: RUS | AO37: 35072 | AP37: Randstad Professional US LP, | AQ37: Billable | AR37: 1 | AW37: VMS Support and Admin | AX37: RT | AY37: RGCC Other Functional Teams | AZ37: 35072 | BC37: Considered | CB37: Billed | CC37: US_SAP_L | CD37: 60002 | CE37: 30001312 | CF37: =A37 -> W0004083 | CG37: Fin | CH37: =SUM(O37,Q37,T37:X37,) -> 108139.35 | CI37: =SUM(AA37,AC37:AE37) -> 7641.9688 | CJ37: =SUM(Z37) -> 5687.5 | CK37: =AJ37 -> 29700 | CL37: =SUM(R37:S37) -> 3730.4647 | CM37: =SUM(AI37,AK37) -> 13166.439 | CO37: =SUM(CH37:CM37,-AL37) -> 0
A38: W0004084 | B38: GCC0619 | C38: Dhwani Modi | D38: 43353 | F38: L10 | G38: HR Capability Center | H38: Shail Dasika | I38: IN - Hyderabad_HQ | K38: Unique | L38: Active | M38: 0.05 | N38: 28 | O38: 61121.667 | R38: 1469.2708 | S38: 0 | T38: 152.80417 | U38: 75 | W38: 0 | X38: 4460.3751 | Y38: 67279.117 | Z38: 12402.5 | AB38: 79681.617 | AH38: 79681.617 | AI38: 3984.0808 | AJ38: 29700 | AK38: 1485 | AL38: 114850.7 | AM38: Randstad Australia | AN38: RGCC Australia | AO38: 6007 | AP38: Randstad Pty Ltd. | AQ38: Billable | AR38: 1 | AW38: Sourcing | AX38: HRCC | AY38: HRCC | AZ38: 6007 | BC38: Considered | CB38: Billed | CC38: AU_RAN_L | CD38: 60014 | CE38: 30001338 | CF38: =A38 -> W0004084 | CG38: HR | CH38: =SUM(O38,Q38,T38:X38,) -> 65809.846 | CI38: =SUM(AA38,AC38:AE38) -> 0 | CJ38: =SUM(Z38) -> 12402.5 | CK38: =AJ38 -> 29700 | CL38: =SUM(R38:S38) -> 1469.2708 | CM38: =SUM(AI38,AK38) -> 5469.0808 | CO38: =SUM(CH38:CM38,-AL38) -> 0
A39: W0004929 | B39: GCC0644 | C39: Steve Decosta | D39: 43381 | F39: L09 | G39: HR Capability Center | H39: Shail Dasika | I39: IN - Hyderabad_HQ | K39: Unique | L39: Active | M39: 0.05 | N39: 28 | O39: 87830 | R39: 1991.1058 | S39: 1150.4167 | T39: 207.075 | U39: 75 | W39: 0 | X39: 4460.3751 | Y39: 95713.973 | Z39: 12402.5 | AB39: 108116.47 | AH39: 108116.47 | AI39: 5405.8236 | AJ39: 29700 | AK39: 1485 | AL39: 144707.3 | AM39: RUS | AN39: RUS | AO39: 90342 | AP39: Randstad Professional US LP, | AQ39: Billable | AR39: 1 | AW39: Call Center | AX39: HRCC | AY39: HRCC | AZ39: 90342 | BC39: Considered | CB39: Billed | CC39: US_SAP_L | CD39: 60002 | CE39: 30001312 | CF39: =A39 -> W0004929 | CG39: HR | CH39: =SUM(O39,Q39,T39:X39,) -> 92572.45 | CI39: =SUM(AA39,AC39:AE39) -> 0 | CJ39: =SUM(Z39) -> 12402.5 | CK39: =AJ39 -> 29700 | CL39: =SUM(R39:S39) -> 3141.5224 | CM39: =SUM(AI39,AK39) -> 6890.8236 | CO39: =SUM(CH39:CM39,-AL39) -> 0
A40: W0004930 | B40: GCC0654 | C40: Pradeep Pereji | D40: 43395 | F40: L11 | G40: Talent Services Capability Center | H40: Ankur Sud | I40: IN - Hyderabad_HQ | K40: Unique | L40: Active | M40: 0.05 | N40: 28 | O40: 59188.5 | R40: 1302.6082 | S40: 0 | T40: 135.47125 | U40: 75 | W40: 0 | X40: 4460.3751 | Y40: 65161.955 | Z40: 4154.1667 | AB40: 69316.121 | AH40: 69316.121 | AI40: 3465.8061 | AJ40: 29700 | AK40: 1485 | AL40: 103966.93 | AM40: RUS | AN40: RUS | AO40: 35070 | AP40: Randstad Professional US LP, | AQ40: Billable | AR40: 1 | AW40: Operations | AX40: RD US | AY40: Digital US - RITS - TPV | AZ40: 35070 | BC40: Considered | CB40: Billed | CC40: US_SAP_L | CD40: 60002 | CE40: 30001312 | CF40: =A40 -> W0004930 | CG40: TS | CH40: =SUM(O40,Q40,T40:X40,) -> 63859.346 | CI40: =SUM(AA40,AC40:AE40) -> 0 | CJ40: =SUM(Z40) -> 4154.1667 | CK40: =AJ40 -> 29700 | CL40: =SUM(R40:S40) -> 1302.6082 | CM40: =SUM(AI40,AK40) -> 4950.8061 | CO40: =SUM(CH40:CM40,-AL40) -> 0
...
